[2025-03-18T15:55:47.329+0000] {local_task_job_runner.py:123} INFO - ::group::Pre task execution logs
[2025-03-18T15:55:47.361+0000] {taskinstance.py:2614} INFO - Dependencies all met for dep_context=non-requeueable deps ti=<TaskInstance: my_first_dag.second_task scheduled__2011-05-15T00:00:00+00:00 [queued]>
[2025-03-18T15:55:47.371+0000] {taskinstance.py:2614} INFO - Dependencies all met for dep_context=requeueable deps ti=<TaskInstance: my_first_dag.second_task scheduled__2011-05-15T00:00:00+00:00 [queued]>
[2025-03-18T15:55:47.372+0000] {taskinstance.py:2867} INFO - Starting attempt 1 of 6
[2025-03-18T15:55:47.392+0000] {taskinstance.py:2890} INFO - Executing <Task(BashOperator): second_task> on 2011-05-15 00:00:00+00:00
[2025-03-18T15:55:47.398+0000] {logging_mixin.py:190} WARNING - /home/***/.local/lib/python3.12/site-packages/***/task/task_runner/standard_task_runner.py:70 DeprecationWarning: This process (pid=6879) is multi-threaded, use of fork() may lead to deadlocks in the child.
[2025-03-18T15:55:47.401+0000] {standard_task_runner.py:72} INFO - Started process 6894 to run task
[2025-03-18T15:55:47.400+0000] {standard_task_runner.py:104} INFO - Running: ['***', 'tasks', 'run', 'my_first_dag', 'second_task', 'scheduled__2011-05-15T00:00:00+00:00', '--job-id', '183', '--raw', '--subdir', 'DAGS_FOLDER/fisrt_dag_1.py', '--cfg-path', '/tmp/tmpugm1cbmu']
[2025-03-18T15:55:47.404+0000] {standard_task_runner.py:105} INFO - Job 183: Subtask second_task
[2025-03-18T15:55:47.489+0000] {task_command.py:467} INFO - Running <TaskInstance: my_first_dag.second_task scheduled__2011-05-15T00:00:00+00:00 [running]> on host 160f03d0fb70
[2025-03-18T15:55:47.639+0000] {taskinstance.py:3134} INFO - Exporting env vars: AIRFLOW_CTX_DAG_OWNER='coder2' AIRFLOW_CTX_DAG_ID='my_first_dag' AIRFLOW_CTX_TASK_ID='second_task' AIRFLOW_CTX_EXECUTION_DATE='2011-05-15T00:00:00+00:00' AIRFLOW_CTX_TRY_NUMBER='1' AIRFLOW_CTX_DAG_RUN_ID='scheduled__2011-05-15T00:00:00+00:00'
[2025-03-18T15:55:47.642+0000] {taskinstance.py:732} INFO - ::endgroup::
[2025-03-18T15:55:47.674+0000] {subprocess.py:78} INFO - Tmp dir root location: /tmp
[2025-03-18T15:55:47.678+0000] {subprocess.py:88} INFO - Running command: ['/usr/bin/bash', '-c', 'second_task']
[2025-03-18T15:55:47.716+0000] {subprocess.py:99} INFO - Output:
[2025-03-18T15:55:47.717+0000] {subprocess.py:106} INFO - /usr/bin/bash: line 1: second_task: command not found
[2025-03-18T15:55:47.719+0000] {subprocess.py:110} INFO - Command exited with return code 127
[2025-03-18T15:55:47.742+0000] {taskinstance.py:3313} ERROR - Task failed with exception
Traceback (most recent call last):
  File "/home/airflow/.local/lib/python3.12/site-packages/airflow/models/taskinstance.py", line 768, in _execute_task
    result = _execute_callable(context=context, **execute_callable_kwargs)
             ^^^^^^^^^^^^^^^^^^^^^^^^^^^^^^^^^^^^^^^^^^^^^^^^^^^^^^^^^^^^^
  File "/home/airflow/.local/lib/python3.12/site-packages/airflow/models/taskinstance.py", line 734, in _execute_callable
    return ExecutionCallableRunner(
           ^^^^^^^^^^^^^^^^^^^^^^^^
  File "/home/airflow/.local/lib/python3.12/site-packages/airflow/utils/operator_helpers.py", line 252, in run
    return self.func(*args, **kwargs)
           ^^^^^^^^^^^^^^^^^^^^^^^^^^
  File "/home/airflow/.local/lib/python3.12/site-packages/airflow/models/baseoperator.py", line 424, in wrapper
    return func(self, *args, **kwargs)
           ^^^^^^^^^^^^^^^^^^^^^^^^^^^
  File "/home/airflow/.local/lib/python3.12/site-packages/airflow/operators/bash.py", line 276, in execute
    raise AirflowException(
airflow.exceptions.AirflowException: Bash command failed. The command returned a non-zero exit code 127.
[2025-03-18T15:55:47.773+0000] {taskinstance.py:1226} INFO - Marking task as UP_FOR_RETRY. dag_id=my_first_dag, task_id=second_task, run_id=scheduled__2011-05-15T00:00:00+00:00, execution_date=20110515T000000, start_date=20250318T155547, end_date=20250318T155547
[2025-03-18T15:55:47.825+0000] {taskinstance.py:341} INFO - ::group::Post task execution logs
[2025-03-18T15:55:47.826+0000] {standard_task_runner.py:124} ERROR - Failed to execute job 183 for task second_task (Bash command failed. The command returned a non-zero exit code 127.; 6894)
Traceback (most recent call last):
  File "/home/airflow/.local/lib/python3.12/site-packages/airflow/task/task_runner/standard_task_runner.py", line 117, in _start_by_fork
    ret = args.func(args, dag=self.dag)
          ^^^^^^^^^^^^^^^^^^^^^^^^^^^^^
  File "/home/airflow/.local/lib/python3.12/site-packages/airflow/cli/cli_config.py", line 49, in command
    return func(*args, **kwargs)
           ^^^^^^^^^^^^^^^^^^^^^
  File "/home/airflow/.local/lib/python3.12/site-packages/airflow/utils/cli.py", line 116, in wrapper
    return f(*args, **kwargs)
           ^^^^^^^^^^^^^^^^^^
  File "/home/airflow/.local/lib/python3.12/site-packages/airflow/cli/commands/task_command.py", line 483, in task_run
    task_return_code = _run_task_by_selected_method(args, _dag, ti)
                       ^^^^^^^^^^^^^^^^^^^^^^^^^^^^^^^^^^^^^^^^^^^^
  File "/home/airflow/.local/lib/python3.12/site-packages/airflow/cli/commands/task_command.py", line 256, in _run_task_by_selected_method
    return _run_raw_task(args, ti)
           ^^^^^^^^^^^^^^^^^^^^^^^
  File "/home/airflow/.local/lib/python3.12/site-packages/airflow/cli/commands/task_command.py", line 341, in _run_raw_task
    return ti._run_raw_task(
           ^^^^^^^^^^^^^^^^^
  File "/home/airflow/.local/lib/python3.12/site-packages/airflow/utils/session.py", line 97, in wrapper
    return func(*args, session=session, **kwargs)
           ^^^^^^^^^^^^^^^^^^^^^^^^^^^^^^^^^^^^^^
  File "/home/airflow/.local/lib/python3.12/site-packages/airflow/models/taskinstance.py", line 3006, in _run_raw_task
    return _run_raw_task(
           ^^^^^^^^^^^^^^
  File "/home/airflow/.local/lib/python3.12/site-packages/airflow/models/taskinstance.py", line 274, in _run_raw_task
    TaskInstance._execute_task_with_callbacks(
  File "/home/airflow/.local/lib/python3.12/site-packages/airflow/models/taskinstance.py", line 3161, in _execute_task_with_callbacks
    result = self._execute_task(context, task_orig)
             ^^^^^^^^^^^^^^^^^^^^^^^^^^^^^^^^^^^^^^
  File "/home/airflow/.local/lib/python3.12/site-packages/airflow/models/taskinstance.py", line 3185, in _execute_task
    return _execute_task(self, context, task_orig)
           ^^^^^^^^^^^^^^^^^^^^^^^^^^^^^^^^^^^^^^^
  File "/home/airflow/.local/lib/python3.12/site-packages/airflow/models/taskinstance.py", line 768, in _execute_task
    result = _execute_callable(context=context, **execute_callable_kwargs)
             ^^^^^^^^^^^^^^^^^^^^^^^^^^^^^^^^^^^^^^^^^^^^^^^^^^^^^^^^^^^^^
  File "/home/airflow/.local/lib/python3.12/site-packages/airflow/models/taskinstance.py", line 734, in _execute_callable
    return ExecutionCallableRunner(
           ^^^^^^^^^^^^^^^^^^^^^^^^
  File "/home/airflow/.local/lib/python3.12/site-packages/airflow/utils/operator_helpers.py", line 252, in run
    return self.func(*args, **kwargs)
           ^^^^^^^^^^^^^^^^^^^^^^^^^^
  File "/home/airflow/.local/lib/python3.12/site-packages/airflow/models/baseoperator.py", line 424, in wrapper
    return func(self, *args, **kwargs)
           ^^^^^^^^^^^^^^^^^^^^^^^^^^^
  File "/home/airflow/.local/lib/python3.12/site-packages/airflow/operators/bash.py", line 276, in execute
    raise AirflowException(
airflow.exceptions.AirflowException: Bash command failed. The command returned a non-zero exit code 127.
[2025-03-18T15:55:47.888+0000] {local_task_job_runner.py:266} INFO - Task exited with return code 1
[2025-03-18T15:55:47.916+0000] {taskinstance.py:3901} INFO - 0 downstream tasks scheduled from follow-on schedule check
[2025-03-18T15:55:47.921+0000] {local_task_job_runner.py:245} INFO - ::endgroup::
